Workbook

Sheet Research Tracker
A1: CRYSTAL PALACE TRANSFER RESEARCH TRACKER
B2: Research sample | G2: Still Palace-owned | L2: Departed | Q2: Value coverage
B3: 47 players | G3: =COUNTIF(K11:K57,"Still at Palace*") -> 22 | L3: =COUNTIF(K11:K57,"Sold")+COUNTIF(K11:K57,"Released / Free") -> 25 | Q3: =COUNT(O11:O57) -> 47
B5: First-team permanent arrivals | G5: Includes players currently on loan | L5: Sold or released | Q5: Current value or sale fee
A7: VALUATION EQUATIONS — ALL FINANCIAL FIELDS ARE IN € MILLIONS
A8: VALUE USED Current MV if Palace-owned; Sale Fee if departed | I8: VALUE GAIN / LOSS Value Used − Fee Paid | Q8: RETURN ON FEE Value Gain/Loss ÷ Fee Paid | Y8: PERFORMANCE FORMULAS Min/Season, efficiency and rating average
A10: Player | B10: Pos | C10: Age@Signing | D10: Transfer Season | E10: Manager | F10: Transfer Type | G10: Fee Paid (€m) | H10: Club Signed From | I10: Source League | J10: Nationality | K10: Current Status | L10: Current Market Value (€m) | M10: Sale Fee (€m) | N10: Valuation Basis | O10: Value Used (€m) | P10: Gain/Loss Type | Q10: Value Gain/Loss (€m) | R10: Return on Fee (%) | S10: MV at Signing (€m) | T10: Palace Usage | U10: Seasons Played | V10: Usage/Season | W10: Usage/Season per €1m | X10: Rating S1 | Y10: Rating S2 | Z10: Rating S3 | AA10: Rating S4 | AB10: Rating S5 | AC10: Rating S6 | AD10: Rating S7 | AE10: Rating S8 | AF10: Average FotMob Rating | AG10: Value Source URL | AH10: Usage Unit | AI10: Season Data Status | AJ10: Season Data Source
A11: Mamadou Sakho | B11: DF | C11: 27 | D11: 2017/18 | F11: Paid | G11: 28.2 | H11: Liverpool | I11: Premier League | J11: France / Senegal | K11: Released / Free | M11: 0 | N11: =IF(A11="","",IF(LEFT(K11,15)="Still at Palace","Current market value","Sale fee")) -> Sale fee | O11: =IF(K11="Sold",M11,IF(OR(K11="Still at Palace",K11="Still at Palace (on loan)"),L11,0)) -> 0 | P11: =IF(Q11>0,"Gain",IF(Q11<0,"Loss","Neutral")) -> Loss | Q11: =O11-G11 -> -28.2 | R11: =IFERROR(Q11/G11,"") -> -1 | S11: 15 | T11: =SUMIFS('FotMob Seasons'!$F$8:$F$136,'FotMob Seasons'!$A$8:$A$136,A11,'FotMob Seasons'!$H$8:$H$136,"Yes") -> 5223 | U11: =COUNTIFS('FotMob Seasons'!$A$8:$A$136,A11,'FotMob Seasons'!$H$8:$H$136,"Yes") -> 4 | V11: =IFERROR(T11/U11,"") -> 1305.75 | W11: =IFERROR(V11/G11,"") -> 46.303191 | X11: 6.74 | Y11: 6.68 | Z11: 6.16 | AA11: 6.28 | AF11: =IFERROR(AVERAGEIFS('FotMob Seasons'!$G$8:$G$136,'FotMob Seasons'!$A$8:$A$136,A11,'FotMob Seasons'!$H$8:$H$136,"Yes"),"") -> 6.465 | AG11: https://www.transfermarkt.com/crystal-palace/alletransfers/verein/873 | AH11: Minutes | AI11: Complete | AJ11: User-provided FotMob
A12: Alexander Sørloth | B12: FW | C12: 22 | D12: 2017/18 | F12: Paid | G12: 16 | H12: Central Jutland | I12: Super League | J12: Norway | K12: Sold | M12: 20 | N12: =IF(A12="","",IF(LEFT(K12,15)="Still at Palace","Current market value","Sale fee")) -> Sale fee | O12: =IF(K12="Sold",M12,IF(OR(K12="Still at Palace",K12="Still at Palace (on loan)"),L12,0)) -> 20 | P12: =IF(Q12>0,"Gain",IF(Q12<0,"Loss","Neutral")) -> Gain | Q12: =O12-G12 -> 4 | R12: =IFERROR(Q12/G12,"") -> 0.25 | S12: 2 | T12: =SUMIFS('FotMob Seasons'!$F$8:$F$136,'FotMob Seasons'!$A$8:$A$136,A12,'FotMob Seasons'!$H$8:$H$136,"Yes") -> 533 | U12: =COUNTIFS('FotMob Seasons'!$A$8:$A$136,A12,'FotMob Seasons'!$H$8:$H$136,"Yes") -> 2 | V12: =IFERROR(T12/U12,"") -> 266.5 | W12: =IFERROR(V12/G12,"") -> 16.65625 | X12: 6.69 | Y12: 6.08 | AF12: =IFERROR(AVERAGEIFS('FotMob Seasons'!$G$8:$G$136,'FotMob Seasons'!$A$8:$A$136,A12,'FotMob Seasons'!$H$8:$H$136,"Yes"),"") -> 6.385 | AG12: https://www.transfermarkt.com/crystal-palace/alletransfers/verein/873 | AH12: Minutes | AI12: Complete | AJ12: User-provided FotMob
A13: Jaïro Riedewald | B13: MD | C13: 20 | D13: 2017/18 | F13: Paid | G13: 9 | H13: Ajax | I13: Eredivisie | J13: Netherlands / Suriname | K13: Released / Free | M13: 0 | N13: =IF(A13="","",IF(LEFT(K13,15)="Still at Palace","Current market value","Sale fee")) -> Sale fee | O13: =IF(K13="Sold",M13,IF(OR(K13="Still at Palace",K13="Still at Palace (on loan)"),L13,0)) -> 0 | P13: =IF(Q13>0,"Gain",IF(Q13<0,"Loss","Neutral")) -> Loss | Q13: =O13-G13 -> -9 | R13: =IFERROR(Q13/G13,"") -> -1 | S13: 5 | T13: =SUMIFS('FotMob Seasons'!$F$8:$F$136,'FotMob Seasons'!$A$8:$A$136,A13,'FotMob Seasons'!$H$8:$H$136,"Yes") -> 3421 | U13: =COUNTIFS('FotMob Seasons'!$A$8:$A$136,A13,'FotMob Seasons'!$H$8:$H$136,"Yes") -> 7 | V13: =IFERROR(T13/U13,"") -> 488.71429 | W13: =IFERROR(V13/G13,"") -> 54.301587 | X13: 6.31 | Y13: 6.33 | Z13: 6.52 | AA13: 6.27 | AB13: 6.6 | AC13: 6.41 | AF13: =IFERROR(AVERAGEIFS('FotMob Seasons'!$G$8:$G$136,'FotMob Seasons'!$A$8:$A$136,A13,'FotMob Seasons'!$H$8:$H$136,"Yes"),"") -> 6.4066667 | AG13: https://www.transfermarkt.com/crystal-palace/rekordabgaenge/verein/873/saison_id/2024 | AH13: Minutes | AI13: Complete | AJ13: User-provided FotMob
A14: Jarosław Jach | B14: DF | C14: 23 | D14: 2017/18 | F14: Paid | G14: 2.75 | H14: Zagłębie Lubin | I14: Ekstraklasa | J14: Poland | K14: Released / Free | M14: 0 | N14: =IF(A14="","",IF(LEFT(K14,15)="Still at Palace","Current market value","Sale fee")) -> Sale fee | O14: =IF(K14="Sold",M14,IF(OR(K14="Still at Palace",K14="Still at Palace (on loan)"),L14,0)) -> 0 | P14: =IF(Q14>0,"Gain",IF(Q14<0,"Loss","Neutral")) -> Loss | Q14: =O14-G14 -> -2.75 | R14: =IFERROR(Q14/G14,"") -> -1 | S14: 2 | T14: =SUMIFS('FotMob Seasons'!$F$8:$F$136,'FotMob Seasons'!$A$8:$A$136,A14,'FotMob Seasons'!$H$8:$H$136,"Yes") -> 0 | U14: =COUNTIFS('FotMob Seasons'!$A$8:$A$136,A14,'FotMob Seasons'!$H$8:$H$136,"Yes") -> 1 | V14: =IFERROR(T14/U14,"") -> 0 | W14: =IFERROR(V14/G14,"") -> 0 | AF14: =IFERROR(AVERAGEIFS('FotMob Seasons'!$G$8:$G$136,'FotMob Seasons'!$A$8:$A$136,A14,'FotMob Seasons'!$H$8:$H$136,"Yes"),"") | AG14: https://www.transfermarkt.com/crystal-palace/alletransfers/verein/873 | AH14: Minutes | AI14: Complete — no Palace PL usage | AJ14: User-provided FotMob
A15: Diego Cavalieri | B15: GK | C15: 35 | D15: 2017/18 | F15: Free transfer | G15: 0 | H15: Without Club | I15: Without Club | J15: Brazil / Italy | K15: Released / Free | M15: 0 | N15: =IF(A15="","",IF(LEFT(K15,15)="Still at Palace","Current market value","Sale fee")) -> Sale fee | O15: =IF(K15="Sold",M15,IF(OR(K15="Still at Palace",K15="Still at Palace (on loan)"),L15,0)) -> 0 | P15: =IF(Q15>0,"Gain",IF(Q15<0,"Loss","Neutral")) -> Neutral | Q15: =O15-G15 -> 0 | R15: =IFERROR(Q15/G15,"") | S15: 1.75 | T15: =SUMIFS('FotMob Seasons'!$F$8:$F$136,'FotMob Seasons'!$A$8:$A$136,A15,'FotMob Seasons'!$H$8:$H$136,"Yes") -> 0 | U15: =COUNTIFS('FotMob Seasons'!$A$8:$A$136,A15,'FotMob Seasons'!$H$8:$H$136,"Yes") -> 1 | V15: =IFERROR(T15/U15,"") -> 0 | W15: =IFERROR(V15/G15,"") | AF15: =IFERROR(AVERAGEIFS('FotMob Seasons'!$G$8:$G$136,'FotMob Seasons'!$A$8:$A$136,A15,'FotMob Seasons'!$H$8:$H$136,"Yes"),"") | AG15: https://www.transfermarkt.com/crystal-palace/alletransfers/verein/873 | AH15: Matches | AI15: Complete — no Palace PL usage | AJ15: User-provided FotMob
A16: Cheikhou Kouyaté | B16: MD | C16: 28 | D16: 2018/19 | F16: Paid | G16: 10.7 | H16: West Ham | I16: Premier League | J16: Senegal / Belgium | K16: Released / Free | M16: 0 | N16: =IF(A16="","",IF(LEFT(K16,15)="Still at Palace","Current market value","Sale fee")) -> Sale fee | O16: =IF(K16="Sold",M16,IF(OR(K16="Still at Palace",K16="Still at Palace (on loan)"),L16,0)) -> 0 | P16: =IF(Q16>0,"Gain",IF(Q16<0,"Loss","Neutral")) -> Loss | Q16: =O16-G16 -> -10.7 | R16: =IFERROR(Q16/G16,"") -> -1 | S16: 12 | T16: =SUMIFS('FotMob Seasons'!$F$8:$F$136,'FotMob Seasons'!$A$8:$A$136,A16,'FotMob Seasons'!$H$8:$H$136,"Yes") -> 9533 | U16: =COUNTIFS('FotMob Seasons'!$A$8:$A$136,A16,'FotMob Seasons'!$H$8:$H$136,"Yes") -> 4 | V16: =IFERROR(T16/U16,"") -> 2383.25 | W16: =IFERROR(V16/G16,"") -> 222.73364 | X16: 6.46 | Y16: 6.58 | Z16: 6.52 | AA16: 6.99 | AF16: =IFERROR(AVERAGEIFS('FotMob Seasons'!$G$8:$G$136,'FotMob Seasons'!$A$8:$A$136,A16,'FotMob Seasons'!$H$8:$H$136,"Yes"),"") -> 6.6375 | AG16: https://www.transfermarkt.com/crystal-palace/alletransfers/verein/873 | AH16: Minutes | AI16: Complete | AJ16: User-provided FotMob
A17: Max Meyer | B17: MD | C17: 22 | D17: 2018/19 | F17: Free transfer | G17: 0 | H17: FC Schalke 04 | I17: Bundesliga | J17: Germany | K17: Released / Free | M17: 0 | N17: =IF(A17="","",IF(LEFT(K17,15)="Still at Palace","Current market value","Sale fee")) -> Sale fee | O17: =IF(K17="Sold",M17,IF(OR(K17="Still at Palace",K17="Still at Palace (on loan)"),L17,0)) -> 0 | P17: =IF(Q17>0,"Gain",IF(Q17<0,"Loss","Neutral")) -> Neutral | Q17: =O17-G17 -> 0 | R17: =IFERROR(Q17/G17,"") | S17: 18 | T17: =SUMIFS('FotMob Seasons'!$F$8:$F$136,'FotMob Seasons'!$A$8:$A$136,A17,'FotMob Seasons'!$H$8:$H$136,"Yes") -> 2060 | U17: =COUNTIFS('FotMob Seasons'!$A$8:$A$136,A17,'FotMob Seasons'!$H$8:$H$136,"Yes") -> 3 | V17: =IFERROR(T17/U17,"") -> 686.66667 | W17: =IFERROR(V17/G17,"") | X17: 6.47 | Y17: 6.02 | AF17: =IFERROR(AVERAGEIFS('FotMob Seasons'!$G$8:$G$136,'FotMob Seasons'!$A$8:$A$136,A17,'FotMob Seasons'!$H$8:$H$136,"Yes"),"") -> 6.245 | AG17: https://www.transfermarkt.com/crystal-palace/alletransfers/verein/873 | AH17: Minutes | AI17: Complete | AJ17: User-provided FotMob
A18: Bakary Sako | B18: FW | C18: 30 | D18: 2018/19 | F18: Free transfer | G18: 0 | H18: West Brom | I18: Championship | J18: Mali / France | K18: Released / Free | M18: 0 | N18: =IF(A18="","",IF(LEFT(K18,15)="Still at Palace","Current market value","Sale fee")) -> Sale fee | O18: =IF(K18="Sold",M18,IF(OR(K18="Still at Palace",K18="Still at Palace (on loan)"),L18,0)) -> 0 | P18: =IF(Q18>0,"Gain",IF(Q18<0,"Loss","Neutral")) -> Neutral | Q18: =O18-G18 -> 0 | R18: =IFERROR(Q18/G18,"") | S18: 5 | T18: =SUMIFS('FotMob Seasons'!$F$8:$F$136,'FotMob Seasons'!$A$8:$A$136,A18,'FotMob Seasons'!$H$8:$H$136,"Yes") -> 26 | U18: =COUNTIFS('FotMob Seasons'!$A$8:$A$136,A18,'FotMob Seasons'!$H$8:$H$136,"Yes") -> 1 | V18: =IFERROR(T18/U18,"") -> 26 | W18: =IFERROR(V18/G18,"") | X18: 5.87 | AF18: =IFERROR(AVERAGEIFS('FotMob Seasons'!$G$8:$G$136,'FotMob Seasons'!$A$8:$A$136,A18,'FotMob Seasons'!$H$8:$H$136,"Yes"),"") -> 5.87 | AG18: https://www.transfermarkt.com/crystal-palace/alletransfers/verein/873 | AH18: Minutes | AI18: Complete | AJ18: User-provided FotMob
A19: Vicente Guaita | B19: GK | C19: 31 | D19: 2018/19 | F19: Free transfer | G19: 0 | H19: Getafe | I19: LaLiga | J19: Spain | K19: Released / Free | M19: 0 | N19: =IF(A19="","",IF(LEFT(K19,15)="Still at Palace","Current market value","Sale fee")) -> Sale fee | O19: =IF(K19="Sold",M19,IF(OR(K19="Still at Palace",K19="Still at Palace (on loan)"),L19,0)) -> 0 | P19: =IF(Q19>0,"Gain",IF(Q19<0,"Loss","Neutral")) -> Neutral | Q19: =O19-G19 -> 0 | R19: =IFERROR(Q19/G19,"") | S19: 5 | T19: =SUMIFS('FotMob Seasons'!$F$8:$F$136,'FotMob Seasons'!$A$8:$A$136,A19,'FotMob Seasons'!$H$8:$H$136,"Yes") -> 149 | U19: =COUNTIFS('FotMob Seasons'!$A$8:$A$136,A19,'FotMob Seasons'!$H$8:$H$136,"Yes") -> 5 | V19: =IFERROR(T19/U19,"") -> 29.8 | W19: =IFERROR(V19/G19,"") | X19: 6.44 | Y19: 6.46 | Z19: 6.13 | AA19: 6.65 | AB19: 6.66 | AF19: =IFERROR(AVERAGEIFS('FotMob Seasons'!$G$8:$G$136,'FotMob Seasons'!$A$8:$A$136,A19,'FotMob Seasons'!$H$8:$H$136,"Yes"),"") -> 6.468 | AG19: https://www.transfermarkt.com/crystal-palace/alletransfers/verein/873 | AH19: Matches | AI19: Complete | AJ19: User-provided FotMob
A20: James McCarthy | B20: MD | C20: 28 | D20: 2019/20 | F20: Paid | G20: 3.3 | H20: Everton | I20: Premier League | J20: Ireland / Scotland | K20: Released / Free | M20: 0 | N20: =IF(A20="","",IF(LEFT(K20,15)="Still at Palace","Current market value","Sale fee")) -> Sale fee | O20: =IF(K20="Sold",M20,IF(OR(K20="Still at Palace",K20="Still at Palace (on loan)"),L20,0)) -> 0 | P20: =IF(Q20>0,"Gain",IF(Q20<0,"Loss","Neutral")) -> Loss | Q20: =O20-G20 -> -3.3 | R20: =IFERROR(Q20/G20,"") -> -1 | S20: 5 | T20: =SUMIFS('FotMob Seasons'!$F$8:$F$136,'FotMob Seasons'!$A$8:$A$136,A20,'FotMob Seasons'!$H$8:$H$136,"Yes") -> 2495 | U20: =COUNTIFS('FotMob Seasons'!$A$8:$A$136,A20,'FotMob Seasons'!$H$8:$H$136,"Yes") -> 2 | V20: =IFERROR(T20/U20,"") -> 1247.5 | W20: =IFERROR(V20/G20,"") -> 378.0303 | X20: 6.42 | Y20: 6.48 | AF20: =IFERROR(AVERAGEIFS('FotMob Seasons'!$G$8:$G$136,'FotMob Seasons'!$A$8:$A$136,A20,'FotMob Seasons'!$H$8:$H$136,"Yes"),"") -> 6.45 | AG20: https://www.transfermarkt.com/crystal-palace/alletransfers/verein/873 | AH20: Minutes | AI20: Complete | AJ20: User-provided FotMob
A21: Jordan Ayew | B21: FW | C21: 27 | D21: 2019/20 | F21: Paid | G21: 2.8 | H21: Swansea City | I21: Championship | J21: Ghana / France | K21: Sold | M21: 5.9 | N21: =IF(A21="","",IF(LEFT(K21,15)="Still at Palace","Current market value","Sale fee")) -> Sale fee | O21: =IF(K21="Sold",M21,IF(OR(K21="Still at Palace",K21="Still at Palace (on loan)"),L21,0)) -> 5.9 | P21: =IF(Q21>0,"Gain",IF(Q21<0,"Loss","Neutral")) -> Gain | Q21: =O21-G21 -> 3.1 | R21: =IFERROR(Q21/G21,"") -> 1.1071429 | S21: 8 | T21: =SUMIFS('FotMob Seasons'!$F$8:$F$136,'FotMob Seasons'!$A$8:$A$136,A21,'FotMob Seasons'!$H$8:$H$136,"Yes") -> 12594 | U21: =COUNTIFS('FotMob Seasons'!$A$8:$A$136,A21,'FotMob Seasons'!$H$8:$H$136,"Yes") -> 5 | V21: =IFERROR(T21/U21,"") -> 2518.8 | W21: =IFERROR(V21/G21,"") -> 899.57143 | X21: 6.48 | Y21: 6.38 | Z21: 6.75 | AA21: 6.84 | AB21: 7 | AF21: =IFERROR(AVERAGEIFS('FotMob Seasons'!$G$8:$G$136,'FotMob Seasons'!$A$8:$A$136,A21,'FotMob Seasons'!$H$8:$H$136,"Yes"),"") -> 6.69 | AG21: https://www.transfermarkt.com/crystal-palace/rekordabgaenge/verein/873/saison_id/2024 | AH21: Minutes | AI21: Complete | AJ21: User-provided FotMob
A22: Gary Cahill | B22: DF | C22: 33 | D22: 2019/20 | F22: Free transfer | G22: 0 | H22: Chelsea | I22: Premier League | J22: England | K22: Released / Free | M22: 0 | N22: =IF(A22="","",IF(LEFT(K22,15)="Still at Palace","Current market value","Sale fee")) -> Sale fee | O22: =IF(K22="Sold",M22,IF(OR(K22="Still at Palace",K22="Still at Palace (on loan)"),L22,0)) -> 0 | P22: =IF(Q22>0,"Gain",IF(Q22<0,"Loss","Neutral")) -> Neutral | Q22: =O22-G22 -> 0 | R22: =IFERROR(Q22/G22,"") | S22: 8 | T22: =SUMIFS('FotMob Seasons'!$F$8:$F$136,'FotMob Seasons'!$A$8:$A$136,A22,'FotMob Seasons'!$H$8:$H$136,"Yes") -> 3968 | U22: =COUNTIFS('FotMob Seasons'!$A$8:$A$136,A22,'FotMob Seasons'!$H$8:$H$136,"Yes") -> 2 | V22: =IFERROR(T22/U22,"") -> 1984 | W22: =IFERROR(V22/G22,"") | X22: 6.54 | Y22: 6.37 | AF22: =IFERROR(AVERAGEIFS('FotMob Seasons'!$G$8:$G$136,'FotMob Seasons'!$A$8:$A$136,A22,'FotMob Seasons'!$H$8:$H$136,"Yes"),"") -> 6.455 | AG22: https://www.transfermarkt.com/crystal-palace/alletransfers/verein/873 | AH22: Minutes | AI22: Complete | AJ22: User-provided FotMob
A23: Stephen Henderson | B23: GK | C23: 31 | D23: 2019/20 | F23: Free transfer | G23: 0 | H23: Nottingham Forest | I23: Championship | J23: Ireland | K23: Released / Free | M23: 0 | N23: =IF(A23="","",IF(LEFT(K23,15)="Still at Palace","Current market value","Sale fee")) -> Sale fee | O23: =IF(K23="Sold",M23,IF(OR(K23="Still at Palace",K23="Still at Palace (on loan)"),L23,0)) -> 0 | P23: =IF(Q23>0,"Gain",IF(Q23<0,"Loss","Neutral")) -> Neutral | Q23: =O23-G23 -> 0 | R23: =IFERROR(Q23/G23,"") | S23: 0.5 | T23: =SUMIFS('FotMob Seasons'!$F$8:$F$136,'FotMob Seasons'!$A$8:$A$136,A23,'FotMob Seasons'!$H$8:$H$136,"Yes") -> 0 | U23: =COUNTIFS('FotMob Seasons'!$A$8:$A$136,A23,'FotMob Seasons'!$H$8:$H$136,"Yes") -> 1 | V23: =IFERROR(T23/U23,"") -> 0 | W23: =IFERROR(V23/G23,"") | AF23: =IFERROR(AVERAGEIFS('FotMob Seasons'!$G$8:$G$136,'FotMob Seasons'!$A$8:$A$136,A23,'FotMob Seasons'!$H$8:$H$136,"Yes"),"") | AG23: https://www.transfermarkt.com/crystal-palace/alletransfers/verein/873 | AH23: Matches | AI23: Complete — no Palace PL usage | AJ23: User-provided FotMob
A24: Eberechi Eze | B24: MD | C24: 22 | D24: 2020/21 | F24: Paid | G24: 17.8 | H24: QPR | I24: Championship | J24: England / Nigeria | K24: Sold | M24: 69.3 | N24: =IF(A24="","",IF(LEFT(K24,15)="Still at Palace","Current market value","Sale fee")) -> Sale fee | O24: =IF(K24="Sold",M24,IF(OR(K24="Still at Palace",K24="Still at Palace (on loan)"),L24,0)) -> 69.3 | P24: =IF(Q24>0,"Gain",IF(Q24<0,"Loss","Neutral")) -> Gain | Q24: =O24-G24 -> 51.5 | R24: =IFERROR(Q24/G24,"") -> 2.8932584 | S24: 9 | T24: =SUMIFS('FotMob Seasons'!$F$8:$F$136,'FotMob Seasons'!$A$8:$A$136,A24,'FotMob Seasons'!$H$8:$H$136,"Yes") -> 10471 | U24: =COUNTIFS('FotMob Seasons'!$A$8:$A$136,A24,'FotMob Seasons'!$H$8:$H$136,"Yes") -> 5 | V24: =IFERROR(T24/U24,"") -> 2094.2 | W24: =IFERROR(V24/G24,"") -> 117.65169 | X24: 6.92 | Y24: 6.85 | Z24: 7.27 | AA24: 7.6 | AB24: 7.4 | AF24: =IFERROR(AVERAGEIFS('FotMob Seasons'!$G$8:$G$136,'FotMob Seasons'!$A$8:$A$136,A24,'FotMob Seasons'!$H$8:$H$136,"Yes"),"") -> 7.208 | AG24: https://www.transfermarkt.com/crystal-palace/rekordabgaenge/verein/873/saison_id/2025/pos//detailpos/0/w_s//plus/1 | AH24: Minutes | AI24: Complete | AJ24: User-provided FotMob
A25: Jack Butland | B25: GK | C25: 27 | D25: 2020/21 | F25: Paid | G25: 1.1 | H25: Stoke City | I25: Championship | J25: England | K25: Released / Free | M25: 0 | N25: =IF(A25="","",IF(LEFT(K25,15)="Still at Palace","Current market value","Sale fee")) -> Sale fee | O25: =IF(K25="Sold",M25,IF(OR(K25="Still at Palace",K25="Still at Palace (on loan)"),L25,0)) -> 0 | P25: =IF(Q25>0,"Gain",IF(Q25<0,"Loss","Neutral")) -> Loss | Q25: =O25-G25 -> -1.1 | R25: =IFERROR(Q25/G25,"") -> -1 | S25: 3.5 | T25: =SUMIFS('FotMob Seasons'!$F$8:$F$136,'FotMob Seasons'!$A$8:$A$136,A25,'FotMob Seasons'!$H$8:$H$136,"Yes") -> 10 | U25: =COUNTIFS('FotMob Seasons'!$A$8:$A$136,A25,'FotMob Seasons'!$H$8:$H$136,"Yes") -> 2 | V25: =IFERROR(T25/U25,"") -> 5 | W25: =IFERROR(V25/G25,"") -> 4.5454545 | X25: 6.38 | Y25: 6.26 | AF25: =IFERROR(AVERAGEIFS('FotMob Seasons'!$G$8:$G$136,'FotMob Seasons'!$A$8:$A$136,A25,'FotMob Seasons'!$H$8:$H$136,"Yes"),"") -> 6.32 | AG25: https://www.transfermarkt.com/crystal-palace/alletransfers/verein/873 | AH25: Matches | AI25: Complete | AJ25: User-provided FotMob
A26: Nathaniel Clyne | B26: DF | C26: 29 | D26: 2020/21 | F26: Free transfer | G26: 0 | H26: Liverpool | I26: Premier League | J26: England / Grenada | K26: Still at Palace | L26: 0.3 | N26: =IF(A26="","",IF(LEFT(K26,15)="Still at Palace","Current market value","Sale fee")) -> Current market value | O26: =IF(K26="Sold",M26,IF(OR(K26="Still at Palace",K26="Still at Palace (on loan)"),L26,0)) -> 0.3 | P26: =IF(Q26>0,"Gain",IF(Q26<0,"Loss","Neutral")) -> Gain | Q26: =O26-G26 -> 0.3 | R26: =IFERROR(Q26/G26,"") | S26: 8 | T26: =SUMIFS('FotMob Seasons'!$F$8:$F$136,'FotMob Seasons'!$A$8:$A$136,A26,'FotMob Seasons'!$H$8:$H$136,"Yes") -> 6554 | U26: =COUNTIFS('FotMob Seasons'!$A$8:$A$136,A26,'FotMob Seasons'!$H$8:$H$136,"Yes") -> 6 | V26: =IFERROR(T26/U26,"") -> 1092.3333 | W26: =IFERROR(V26/G26,"") | X26: 6.37 | Y26: 6.97 | Z26: 6.6 | AA26: 6.82 | AB26: 6.22 | AC26: 6.68 | AF26: =IFERROR(AVERAGEIFS('FotMob Seasons'!$G$8:$G$136,'FotMob Seasons'!$A$8:$A$136,A26,'FotMob Seasons'!$H$8:$H$136,"Yes"),"") -> 6.61 | AG26: https://www.transfermarkt.com/crystal-palace/marktwertanalyse/verein/873 | AH26: Minutes | AI26: Complete | AJ26: User-provided FotMob
A27: Nathan Ferguson | B27: DF | C27: 19 | D27: 2020/21 | F27: Free transfer | G27: 0 | H27: West Brom | I27: Premier League | J27: England / Jamaica | K27: Released / Free | M27: 0 | N27: =IF(A27="","",IF(LEFT(K27,15)="Still at Palace","Current market value","Sale fee")) -> Sale fee | O27: =IF(K27="Sold",M27,IF(OR(K27="Still at Palace",K27="Still at Palace (on loan)"),L27,0)) -> 0 | P27: =IF(Q27>0,"Gain",IF(Q27<0,"Loss","Neutral")) -> Neutral | Q27: =O27-G27 -> 0 | R27: =IFERROR(Q27/G27,"") | S27: 4 | T27: =SUMIFS('FotMob Seasons'!$F$8:$F$136,'FotMob Seasons'!$A$8:$A$136,A27,'FotMob Seasons'!$H$8:$H$136,"Yes") -> 8 | U27: =COUNTIFS('FotMob Seasons'!$A$8:$A$136,A27,'FotMob Seasons'!$H$8:$H$136,"Yes") -> 4 | V27: =IFERROR(T27/U27,"") -> 2 | W27: =IFERROR(V27/G27,"") | AF27: =IFERROR(AVERAGEIFS('FotMob Seasons'!$G$8:$G$136,'FotMob Seasons'!$A$8:$A$136,A27,'FotMob Seasons'!$H$8:$H$136,"Yes"),"") | AG27: https://www.transfermarkt.com/crystal-palace/rekordabgaenge/verein/873/saison_id/2024 | AH27: Minutes | AI27: Complete — some low-use ratings N/A | AJ27: User-provided FotMob
A28: Marc Guéhi | B28: DF | C28: 21 | D28: 2021/22 | F28: Paid | G28: 23.34 | H28: Chelsea | I28: Premier League | J28: England / Côte d’Ivoire | K28: Sold | M28: 23 | N28: =IF(A28="","",IF(LEFT(K28,15)="Still at Palace","Current market value","Sale fee")) -> Sale fee | O28: =IF(K28="Sold",M28,IF(OR(K28="Still at Palace",K28="Still at Palace (on loan)"),L28,0)) -> 23 | P28: =IF(Q28>0,"Gain",IF(Q28<0,"Loss","Neutral")) -> Loss | Q28: =O28-G28 -> -0.34 | R28: =IFERROR(Q28/G28,"") -> -0.014567266 | S28: 10 | T28: =SUMIFS('FotMob Seasons'!$F$8:$F$136,'FotMob Seasons'!$A$8:$A$136,A28,'FotMob Seasons'!$H$8:$H$136,"Yes") -> 11632 | U28: =COUNTIFS('FotMob Seasons'!$A$8:$A$136,A28,'FotMob Seasons'!$H$8:$H$136,"Yes") -> 4 | V28: =IFERROR(T28/U28,"") -> 2908 | W28: =IFERROR(V28/G28,"") -> 124.59297 | X28: 7.04 | Y28: 7.02 | Z28: 6.79 | AA28: 6.92 | AF28: =IFERROR(AVERAGEIFS('FotMob Seasons'!$G$8:$G$136,'FotMob Seasons'!$A$8:$A$136,A28,'FotMob Seasons'!$H$8:$H$136,"Yes"),"") -> 6.9425 | AG28: https://www.transfermarkt.com/crystal-palace/rekordabgaenge/verein/873/saison_id/2025/pos//detailpos/0/w_s//plus/1 | AH28: Minutes | AI28: Complete | AJ28: User-provided FotMob
A29: Joachim Andersen | B29: DF | C29: 25 | D29: 2021/22 | F29: Paid | G29: 17.5 | H29: Lyon | I29: Ligue 1 | J29: Denmark | K29: Sold | M29: 29.5 | N29: =IF(A29="","",IF(LEFT(K29,15)="Still at Palace","Current market value","Sale fee")) -> Sale fee | O29: =IF(K29="Sold",M29,IF(OR(K29="Still at Palace",K29="Still at Palace (on loan)"),L29,0)) -> 29.5 | P29: =IF(Q29>0,"Gain",IF(Q29<0,"Loss","Neutral")) -> Gain | Q29: =O29-G29 -> 12 | R29: =IFERROR(Q29/G29,"") -> 0.68571429 | S29: 22 | T29: =SUMIFS('FotMob Seasons'!$F$8:$F$136,'FotMob Seasons'!$A$8:$A$136,A29,'FotMob Seasons'!$H$8:$H$136,"Yes") -> 9114 | U29: =COUNTIFS('FotMob Seasons'!$A$8:$A$136,A29,'FotMob Seasons'!$H$8:$H$136,"Yes") -> 3 | V29: =IFERROR(T29/U29,"") -> 3038 | W29: =IFERROR(V29/G29,"") -> 173.6 | X29: 6.91 | Y29: 7.06 | Z29: 7.03 | AF29: =IFERROR(AVERAGEIFS('FotMob Seasons'!$G$8:$G$136,'FotMob Seasons'!$A$8:$A$136,A29,'FotMob Seasons'!$H$8:$H$136,"Yes"),"") -> 7 | AG29: https://www.transfermarkt.com/crystal-palace/rekordabgaenge/verein/873/saison_id/2024 | AH29: Minutes | AI29: Complete | AJ29: FotMob via CraftedFC
A30: Odsonne Édouard | B30: FW | C30: 23 | D30: 2021/22 | F30: Paid | G30: 16.3 | H30: Celtic | I30: Premiership | J30: France / Haiti | K30: Sold | M30: 3.7 | N30: =IF(A30="","",IF(LEFT(K30,15)="Still at Palace","Current market value","Sale fee")) -> Sale fee | O30: =IF(K30="Sold",M30,IF(OR(K30="Still at Palace",K30="Still at Palace (on loan)"),L30,0)) -> 3.7 | P30: =IF(Q30>0,"Gain",IF(Q30<0,"Loss","Neutral")) -> Loss | Q30: =O30-G30 -> -12.6 | R30: =IFERROR(Q30/G30,"") -> -0.77300613 | S30: 17 | T30: =SUMIFS('FotMob Seasons'!$F$8:$F$136,'FotMob Seasons'!$A$8:$A$136,A30,'FotMob Seasons'!$H$8:$H$136,"Yes") -> 4924 | U30: =COUNTIFS('FotMob Seasons'!$A$8:$A$136,A30,'FotMob Seasons'!$H$8:$H$136,"Yes") -> 3 | V30: =IFERROR(T30/U30,"") -> 1641.3333 | W30: =IFERROR(V30/G30,"") -> 100.6953 | X30: 6.78 | Y30: 6.43 | Z30: 6.75 | AF30: =IFERROR(AVERAGEIFS('FotMob Seasons'!$G$8:$G$136,'FotMob Seasons'!$A$8:$A$136,A30,'FotMob Seasons'!$H$8:$H$136,"Yes"),"") -> 6.6533333 | AG30: https://www.transfermarkt.com/crystal-palace/rekordabgaenge/verein/873/saison_id/2025/pos//detailpos/0/w_s//plus/1 | AH30: Minutes | AI30: Complete; 1 partial season excluded | AJ30: FotMob via CraftedFC
A31: Jean-Philippe Mateta | B31: FW | C31: 24 | D31: 2021/22 | F31: Paid | G31: 11 | H31: Mainz | I31: Bundesliga | J31: France / DR Congo | K31: Still at Palace | L31: 30 | N31: =IF(A31="","",IF(LEFT(K31,15)="Still at Palace","Current market value","Sale fee")) -> Current market value | O31: =IF(K31="Sold",M31,IF(OR(K31="Still at Palace",K31="Still at Palace (on loan)"),L31,0)) -> 30 | P31: =IF(Q31>0,"Gain",IF(Q31<0,"Loss","Neutral")) -> Gain | Q31: =O31-G31 -> 19 | R31: =IFERROR(Q31/G31,"") -> 1.7272727 | S31: 6 | T31: =SUMIFS('FotMob Seasons'!$F$8:$F$136,'FotMob Seasons'!$A$8:$A$136,A31,'FotMob Seasons'!$H$8:$H$136,"Yes") -> 9061 | U31: =COUNTIFS('FotMob Seasons'!$A$8:$A$136,A31,'FotMob Seasons'!$H$8:$H$136,"Yes") -> 5 | V31: =IFERROR(T31/U31,"") -> 1812.2 | W31: =IFERROR(V31/G31,"") -> 164.74545 | X31: 6.6 | Y31: 6.15 | Z31: 6.95 | AA31: 6.86 | AB31: 6.68 | AF31: =IFERROR(AVERAGEIFS('FotMob Seasons'!$G$8:$G$136,'FotMob Seasons'!$A$8:$A$136,A31,'FotMob Seasons'!$H$8:$H$136,"Yes"),"") -> 6.648 | AG31: https://www.transfermarkt.com/crystal-palace/marktwertanalyse/verein/873 | AH31: Minutes | AI31: Complete | AJ31: FotMob via CraftedFC
A32: Michael Olise | B32: FW | C32: 19 | D32: 2021/22 | F32: Paid | G32: 9.3 | H32: Reading | I32: Championship | J32: France / England | K32: Sold | M32: 53 | N32: =IF(A32="","",IF(LEFT(K32,15)="Still at Palace","Current market value","Sale fee")) -> Sale fee | O32: =IF(K32="Sold",M32,IF(OR(K32="Still at Palace",K32="Still at Palace (on loan)"),L32,0)) -> 53 | P32: =IF(Q32>0,"Gain",IF(Q32<0,"Loss","Neutral")) -> Gain | Q32: =O32-G32 -> 43.7 | R32: =IFERROR(Q32/G32,"") -> 4.6989247 | S32: 15 | T32: =SUMIFS('FotMob Seasons'!$F$8:$F$136,'FotMob Seasons'!$A$8:$A$136,A32,'FotMob Seasons'!$H$8:$H$136,"Yes") -> 5170 | U32: =COUNTIFS('FotMob Seasons'!$A$8:$A$136,A32,'FotMob Seasons'!$H$8:$H$136,"Yes") -> 3 | V32: =IFERROR(T32/U32,"") -> 1723.3333 | W32: =IFERROR(V32/G32,"") -> 185.30466 | X32: 6.95 | Y32: 7.25 | Z32: 7.71 | AF32: =IFERROR(AVERAGEIFS('FotMob Seasons'!$G$8:$G$136,'FotMob Seasons'!$A$8:$A$136,A32,'FotMob Seasons'!$H$8:$H$136,"Yes"),"") -> 7.3033333 | AG32: https://www.transfermarkt.com/crystal-palace/rekordabgaenge/verein/873/saison_id/2024 | AH32: Minutes | AI32: Complete | AJ32: FotMob via CraftedFC
A33: Will Hughes | B33: MD | C33: 26 | D33: 2021/22 | F33: Paid | G33: 7 | H33: Watford | I33: Premier League | J33: England | K33: Still at Palace | L33: 5 | N33: =IF(A33="","",IF(LEFT(K33,15)="Still at Palace","Current market value","Sale fee")) -> Current market value | O33: =IF(K33="Sold",M33,IF(OR(K33="Still at Palace",K33="Still at Palace (on loan)"),L33,0)) -> 5 | P33: =IF(Q33>0,"Gain",IF(Q33<0,"Loss","Neutral")) -> Loss | Q33: =O33-G33 -> -2 | R33: =IFERROR(Q33/G33,"") -> -0.28571429 | S33: 7 | T33: =SUMIFS('FotMob Seasons'!$F$8:$F$136,'FotMob Seasons'!$A$8:$A$136,A33,'FotMob Seasons'!$H$8:$H$136,"Yes") -> 7470 | U33: =COUNTIFS('FotMob Seasons'!$A$8:$A$136,A33,'FotMob Seasons'!$H$8:$H$136,"Yes") -> 5 | V33: =IFERROR(T33/U33,"") -> 1494 | W33: =IFERROR(V33/G33,"") -> 213.42857 | X33: 6.53 | Y33: 6.78 | Z33: 6.72 | AA33: 6.56 | AF33: =IFERROR(AVERAGEIFS('FotMob Seasons'!$G$8:$G$136,'FotMob Seasons'!$A$8:$A$136,A33,'FotMob Seasons'!$H$8:$H$136,"Yes"),"") -> 6.71 | AG33: https://www.transfermarkt.com/crystal-palace/marktwertanalyse/verein/873 | AH33: Minutes | AI33: Complete — some low-use ratings N/A | AJ33: FotMob via CraftedFC
A34: Remi Matthews | B34: GK | C34: 27 | D34: 2021/22 | F34: Free transfer | G34: 0 | H34: Sunderland | I34: League One | J34: England | K34: Still at Palace | L34: 0.2 | N34: =IF(A34="","",IF(LEFT(K34,15)="Still at Palace","Current market value","Sale fee")) -> Current market value | O34: =IF(K34="Sold",M34,IF(OR(K34="Still at Palace",K34="Still at Palace (on loan)"),L34,0)) -> 0.2 | P34: =IF(Q34>0,"Gain",IF(Q34<0,"Loss","Neutral")) -> Gain | Q34: =O34-G34 -> 0.2 | R34: =IFERROR(Q34/G34,"") | S34: 0.3 | T34: =SUMIFS('FotMob Seasons'!$F$8:$F$136,'FotMob Seasons'!$A$8:$A$136,A34,'FotMob Seasons'!$H$8:$H$136,"Yes") -> 1 | U34: =COUNTIFS('FotMob Seasons'!$A$8:$A$136,A34,'FotMob Seasons'!$H$8:$H$136,"Yes") -> 4 | V34: =IFERROR(T34/U34,"") -> 0.25 | W34: =IFERROR(V34/G34,"") | AF34: =IFERROR(AVERAGEIFS('FotMob Seasons'!$G$8:$G$136,'FotMob Seasons'!$A$8:$A$136,A34,'FotMob Seasons'!$H$8:$H$136,"Yes"),"") | AG34: https://www.transfermarkt.com/crystal-palace/marktwertanalyse/verein/873 | AH34: Matches | AI34: Complete — some low-use ratings N/A | AJ34: FotMob / official PL
A35: Cheick Doucouré | B35: MD | C35: 22 | D35: 2022/23 | F35: Paid | G35: 22.6 | H35: Lens | I35: Ligue 1 | J35: Mali | K35: Still at Palace | L35: 10 | N35: =IF(A35="","",IF(LEFT(K35,15)="Still at Palace","Current market value","Sale fee")) -> Current market value | O35: =IF(K35="Sold",M35,IF(OR(K35="Still at Palace",K35="Still at Palace (on loan)"),L35,0)) -> 10 | P35: =IF(Q35>0,"Gain",IF(Q35<0,"Loss","Neutral")) -> Loss | Q35: =O35-G35 -> -12.6 | R35: =IFERROR(Q35/G35,"") -> -0.55752212 | S35: 15 | T35: =SUMIFS('FotMob Seasons'!$F$8:$F$136,'FotMob Seasons'!$A$8:$A$136,A35,'FotMob Seasons'!$H$8:$H$136,"Yes") -> 4211 | U35: =COUNTIFS('FotMob Seasons'!$A$8:$A$136,A35,'FotMob Seasons'!$H$8:$H$136,"Yes") -> 4 | V35: =IFERROR(T35/U35,"") -> 1052.75 | W35: =IFERROR(V35/G35,"") -> 46.581858 | X35: 7.12 | AF35: =IFERROR(AVERAGEIFS('FotMob Seasons'!$G$8:$G$136,'FotMob Seasons'!$A$8:$A$136,A35,'FotMob Seasons'!$H$8:$H$136,"Yes"),"") -> 6.9766667 | AG35: https://www.transfermarkt.com/crystal-palace/marktwertanalyse/verein/873 | AH35: Minutes | AI35: Complete — some low-use ratings N/A | AJ35: FotMob / official usage backup
A36: Chris Richards | B36: DF | C36: 22 | D36: 2022/23 | F36: Paid | G36: 12 | H36: Bayern Munich | I36: Bundesliga | J36: USA | K36: Still at Palace | L36: 28 | N36: =IF(A36="","",IF(LEFT(K36,15)="Still at Palace","Current market value","Sale fee")) -> Current market value | O36: =IF(K36="Sold",M36,IF(OR(K36="Still at Palace",K36="Still at Palace (on loan)"),L36,0)) -> 28 | P36: =IF(Q36>0,"Gain",IF(Q36<0,"Loss","Neutral")) -> Gain | Q36: =O36-G36 -> 16 | R36: =IFERROR(Q36/G36,"") -> 1.3333333 | S36: 7.5 | T36: =SUMIFS('FotMob Seasons'!$F$8:$F$136,'FotMob Seasons'!$A$8:$A$136,A36,'FotMob Seasons'!$H$8:$H$136,"Yes") -> 7284 | U36: =COUNTIFS('FotMob Seasons'!$A$8:$A$136,A36,'FotMob Seasons'!$H$8:$H$136,"Yes") -> 4 | V36: =IFERROR(T36/U36,"") -> 1821 | W36: =IFERROR(V36/G36,"") -> 151.75 | X36: 6.84 | Y36: 6.68 | Z36: 6.87 | AF36: =IFERROR(AVERAGEIFS('FotMob Seasons'!$G$8:$G$136,'FotMob Seasons'!$A$8:$A$136,A36,'FotMob Seasons'!$H$8:$H$136,"Yes"),"") -> 6.7725 | AG36: https://www.transfermarkt.com/crystal-palace/marktwertanalyse/verein/873 | AH36: Minutes | AI36: Complete — some low-use ratings N/A | AJ36: FotMob via CraftedFC
A37: Naouirou Ahamada | B37: MD | C37: 20 | D37: 2022/23 | F37: Paid | G37: 12 | H37: Stuttgart | I37: Bundesliga | J37: France / Comoros | K37: Released / Free | M37: 0 | N37: =IF(A37="","",IF(LEFT(K37,15)="Still at Palace","Current market value","Sale fee")) -> Sale fee | O37: =IF(K37="Sold",M37,IF(OR(K37="Still at Palace",K37="Still at Palace (on loan)"),L37,0)) -> 0 | P37: =IF(Q37>0,"Gain",IF(Q37<0,"Loss","Neutral")) -> Loss | Q37: =O37-G37 -> -12 | R37: =IFERROR(Q37/G37,"") -> -1 | S37: 5.5 | T37: =SUMIFS('FotMob Seasons'!$F$8:$F$136,'FotMob Seasons'!$A$8:$A$136,A37,'FotMob Seasons'!$H$8:$H$136,"Yes") -> 419 | U37: =COUNTIFS('FotMob Seasons'!$A$8:$A$136,A37,'FotMob Seasons'!$H$8:$H$136,"Yes") -> 2 | V37: =IFERROR(T37/U37,"") -> 209.5 | W37: =IFERROR(V37/G37,"") -> 17.458333 | AF37: =IFERROR(AVERAGEIFS('FotMob Seasons'!$G$8:$G$136,'FotMob Seasons'!$A$8:$A$136,A37,'FotMob Seasons'!$H$8:$H$136,"Yes"),"") -> 6.18 | AG37: https://www.transfermarkt.com/crystal-palace/rekordabgaenge/verein/873/saison_id/2025/pos//detailpos/0/w_s//plus/1 | AH37: Minutes | AI37: Complete — some low-use ratings N/A | AJ37: FotMob / official usage backup
A38: Sam Johnstone | B38: GK | C38: 29 | D38: 2022/23 | F38: Free transfer | G38: 0 | H38: West Brom | I38: Championship | J38: England | K38: Sold | M38: 11.9 | N38: =IF(A38="","",IF(LEFT(K38,15)="Still at Palace","Current market value","Sale fee")) -> Sale fee | O38: =IF(K38="Sold",M38,IF(OR(K38="Still at Palace",K38="Still at Palace (on loan)"),L38,0)) -> 11.9 | P38: =IF(Q38>0,"Gain",IF(Q38<0,"Loss","Neutral")) -> Gain | Q38: =O38-G38 -> 11.9 | R38: =IFERROR(Q38/G38,"") | S38: 12 | T38: =SUMIFS('FotMob Seasons'!$F$8:$F$136,'FotMob Seasons'!$A$8:$A$136,A38,'FotMob Seasons'!$H$8:$H$136,"Yes") -> 29 | U38: =COUNTIFS('FotMob Seasons'!$A$8:$A$136,A38,'FotMob Seasons'!$H$8:$H$136,"Yes") -> 2 | V38: =IFERROR(T38/U38,"") -> 14.5 | W38: =IFERROR(V38/G38,"") | X38: 6.56 | AF38: =IFERROR(AVERAGEIFS('FotMob Seasons'!$G$8:$G$136,'FotMob Seasons'!$A$8:$A$136,A38,'FotMob Seasons'!$H$8:$H$136,"Yes"),"") -> 6.56 | AG38: https://www.transfermarkt.com/crystal-palace/rekordabgaenge/verein/873/saison_id/2024 | AH38: Matches | AI38: Complete — some low-use ratings N/A | AJ38: FotMob / official PL
A39: Malcolm Ebiowei | B39: FW | C39: 18 | D39: 2022/23 | F39: Free transfer | G39: 0 | H39: Derby County | I39: League One | J39: England / Netherlands | K39: Sold | M39: 1.15 | N39: =IF(A39="","",IF(LEFT(K39,15)="Still at Palace","Current market value","Sale fee")) -> Sale fee | O39: =IF(K39="Sold",M39,IF(OR(K39="Still at Palace",K39="Still at Palace (on loan)"),L39,0)) -> 1.15 | P39: =IF(Q39>0,"Gain",IF(Q39<0,"Loss","Neutral")) -> Gain | Q39: =O39-G39 -> 1.15 | R39: =IFERROR(Q39/G39,"") | S39: 1 | T39: =SUMIFS('FotMob Seasons'!$F$8:$F$136,'FotMob Seasons'!$A$8:$A$136,A39,'FotMob Seasons'!$H$8:$H$136,"Yes") -> 31 | U39: =COUNTIFS('FotMob Seasons'!$A$8:$A$136,A39,'FotMob Seasons'!$H$8:$H$136,"Yes") -> 1 | V39: =IFERROR(T39/U39,"") -> 31 | W39: =IFERROR(V39/G39,"") | AF39: =IFERROR(AVERAGEIFS('FotMob Seasons'!$G$8:$G$136,'FotMob Seasons'!$A$8:$A$136,A39,'FotMob Seasons'!$H$8:$H$136,"Yes"),"") | AG39: https://www.transfermarkt.com/crystal-palace/rekordabgaenge/verein/873/saison_id/2025/pos//detailpos/0/w_s//plus/1 | AH39: Minutes | AI39: Complete — some low-use ratings N/A | AJ39: FotMob / official usage backup
A40: Adam Wharton | B40: MD | C40: 19 | D40: 2023/24 | F40: Paid | G40: 21.1 | H40: Blackburn Rovers | I40: Championship | J40: England | K40: Still at Palace | L40: 70 | N40: =IF(A40="","",IF(LEFT(K40,15)="Still at Palace","Current market value","Sale fee")) -> Current market value | O40: =IF(K40="Sold",M40,IF(OR(K40="Still at Palace",K40="Still at Palace (on loan)"),L40,0)) -> 70 | P40: =IF(Q40>0,"Gain",IF(Q40<0,"Loss","Neutral")) -> Gain | Q40: =O40-G40 -> 48.9 | R40: =IFERROR(Q40/G40,"") -> 2.3175355 | S40: 10 | T40: =SUMIFS('FotMob Seasons'!$F$8:$F$136,'FotMob Seasons'!$A$8:$A$136,A40,'FotMob Seasons'!$H$8:$H$136,"Yes") -> 5193 | U40: =COUNTIFS('FotMob Seasons'!$A$8:$A$136,A40,'FotMob Seasons'!$H$8:$H$136,"Yes") -> 3 | V40: =IFERROR(T40/U40,"") -> 1731 | W40: =IFERROR(V40/G40,"") -> 82.037915 | X40: 7.01 | AF40: =IFERROR(AVERAGEIFS('FotMob Seasons'!$G$8:$G$136,'FotMob Seasons'!$A$8:$A$136,A40,'FotMob Seasons'!$H$8:$H$136,"Yes"),"") -> 7.06 | AG40: https://www.transfermarkt.com/crystal-palace/marktwertanalyse/verein/873 | AH40: Minutes | AI40: Complete — some low-use ratings N/A | AJ40: FotMob via CraftedFC
A41: Matheus França | B41: MD | C41: 19 | D41: 2023/24 | F41: Paid | G41: 20 | H41: Flamengo | I41: Série A | J41: Brazil | K41: Still at Palace (on loan) | L41: 6 | N41: =IF(A41="","",IF(LEFT(K41,15)="Still at Palace","Current market value","Sale fee")) -> Current market value | O41: =IF(K41="Sold",M41,IF(OR(K41="Still at Palace",K41="Still at Palace (on loan)"),L41,0)) -> 6 | P41: =IF(Q41>0,"Gain",IF(Q41<0,"Loss","Neutral")) -> Loss | Q41: =O41-G41 -> -14 | R41: =IFERROR(Q41/G41,"") -> -0.7 | S41: 9 | T41: =SUMIFS('FotMob Seasons'!$F$8:$F$136,'FotMob Seasons'!$A$8:$A$136,A41,'FotMob Seasons'!$H$8:$H$136,"Yes") -> 276 | U41: =COUNTIFS('FotMob Seasons'!$A$8:$A$136,A41,'FotMob Seasons'!$H$8:$H$136,"Yes") -> 2 | V41: =IFERROR(T41/U41,"") -> 138 | W41: =IFERROR(V41/G41,"") -> 6.9 | AF41: =IFERROR(AVERAGEIFS('FotMob Seasons'!$G$8:$G$136,'FotMob Seasons'!$A$8:$A$136,A41,'FotMob Seasons'!$H$8:$H$136,"Yes"),"") -> 6.34 | AG41: https://www.transfermarkt.com/crystal-palace/marktwertanalyse/verein/873 | AH41: Minutes | AI41: Complete — some low-use ratings N/A | AJ41: FotMob / official usage backup
A42: Dean Henderson | B42: GK | C42: 26 | D42: 2023/24 | F42: Paid | G42: 17.5 | H42: Manchester United | I42: Premier League | J42: England | K42: Still at Palace | L42: 28 | N42: =IF(A42="","",IF(LEFT(K42,15)="Still at Palace","Current market value","Sale fee")) -> Current market value | O42: =IF(K42="Sold",M42,IF(OR(K42="Still at Palace",K42="Still at Palace (on loan)"),L42,0)) -> 28 | P42: =IF(Q42>0,"Gain",IF(Q42<0,"Loss","Neutral")) -> Gain | Q42: =O42-G42 -> 10.5 | R42: =IFERROR(Q42/G42,"") -> 0.6 | S42: 18 | T42: =SUMIFS('FotMob Seasons'!$F$8:$F$136,'FotMob Seasons'!$A$8:$A$136,A42,'FotMob Seasons'!$H$8:$H$136,"Yes") -> 93 | U42: =COUNTIFS('FotMob Seasons'!$A$8:$A$136,A42,'FotMob Seasons'!$H$8:$H$136,"Yes") -> 3 | V42: =IFERROR(T42/U42,"") -> 31 | W42: =IFERROR(V42/G42,"") -> 1.7714286 | X42: 7.03 | Y42: 7.01 | AF42: =IFERROR(AVERAGEIFS('FotMob Seasons'!$G$8:$G$136,'FotMob Seasons'!$A$8:$A$136,A42,'FotMob Seasons'!$H$8:$H$136,"Yes"),"") -> 7.02 | AG42: https://www.transfermarkt.com/crystal-palace/marktwertanalyse/verein/873 | AH42: Matches | AI42: Complete — some low-use ratings N/A | AJ42: FotMob via CraftedFC
A43: Daniel Muñoz | B43: DF | C43: 27 | D43: 2023/24 | F43: Paid | G43: 8 | H43: Genk | I43: Jupiler Pro League | J43: Colombia | K43: Still at Palace | L43: 22 | N43: =IF(A43="","",IF(LEFT(K43,15)="Still at Palace","Current market value","Sale fee")) -> Current market value | O43: =IF(K43="Sold",M43,IF(OR(K43="Still at Palace",K43="Still at Palace (on loan)"),L43,0)) -> 22 | P43: =IF(Q43>0,"Gain",IF(Q43<0,"Loss","Neutral")) -> Gain | Q43: =O43-G43 -> 14 | R43: =IFERROR(Q43/G43,"") -> 1.75 | S43: 10 | T43: =SUMIFS('FotMob Seasons'!$F$8:$F$136,'FotMob Seasons'!$A$8:$A$136,A43,'FotMob Seasons'!$H$8:$H$136,"Yes") -> 7075 | U43: =COUNTIFS('FotMob Seasons'!$A$8:$A$136,A43,'FotMob Seasons'!$H$8:$H$136,"Yes") -> 3 | V43: =IFERROR(T43/U43,"") -> 2358.3333 | W43: =IFERROR(V43/G43,"") -> 294.79167 | X43: 7.38 | Y43: 7.15 | AF43: =IFERROR(AVERAGEIFS('FotMob Seasons'!$G$8:$G$136,'FotMob Seasons'!$A$8:$A$136,A43,'FotMob Seasons'!$H$8:$H$136,"Yes"),"") -> 7.2866667 | AG43: https://www.transfermarkt.com/crystal-palace/marktwertanalyse/verein/873 | AH43: Minutes | AI43: Complete — some low-use ratings N/A | AJ43: FotMob via CraftedFC
...

Sheet Method & Sources
A1: VALUATION METHOD AND SOURCES
A3: Item | B3: Method | C3: Formula | D3: Source | E3: Currency | F3: Interpretation | G3: Key limitation | H3: Checked
A4: Still Palace-owned players | B4: Use latest Transfermarkt current market value | C4: Value Used = Current Market Value | D4: https://www.transfermarkt.com/crystal-palace/kader/verein/873 | E4: EUR millions | F4: Unrealised value estimate | G4: Market value is an estimate, not a guaranteed sale price. | H4: 29-Jul-2026
A5: Sold players | B5: Use Transfermarkt-listed departure fee | C5: Value Used = Sale Fee | D5: https://www.transfermarkt.com/crystal-palace/alletransfers/verein/873 | E5: EUR millions | F5: Realised transfer value | G5: Listed fees may omit or simplify add-ons, sell-on clauses or shared proceeds. | H5: 29-Jul-2026
A6: Released / free departures | B6: Record sale fee as zero | C6: Value Used = €0m | D6: https://www.transfermarkt.com/crystal-palace/alletransfers/verein/873 | E6: EUR millions | F6: Realised transfer value | G6: Does not include saved wages or termination costs. | H6: 29-Jul-2026
A7: Value Gain/Loss | B7: Compare a consistent EUR value with the original EUR fee | C7: Value Used − Fee Paid | D7: Workbook formula | E7: EUR millions | F7: Positive = gain; negative = loss | G7: Excludes wages, bonuses, agent fees, add-ons, amortisation and financing. | H7: Automatic
A8: Return on Fee | B8: Scale gain/loss by the original fee | C8: Value Gain/Loss ÷ Fee Paid | D8: Workbook formula | E8: Percentage | F8: Relative transfer-value return | G8: Blank for free transfers because division by zero is not meaningful. | H8: Automatic
A11: IMPORTANT DATA NOTE
A12: The previous workbook mixed pound-denominated labels with euro-denominated Transfermarkt data. This version standardises the original fees, current market values and sale fees to euros, so the gain/loss formulas compare like with like. For players still owned by Palace, the result is unrealised; for departed players, it is realised. Transfermarkt values and reported fees should be treated as consistent research estimates rather than audited accounting figures.

Sheet FotMob Seasons
A1: CRYSTAL PALACE — FOTMOB PREMIER LEAGUE SEASON DATA
A3: PLAYERS | C3: SEASON ROWS | E3: RATED SEASONS | G3: COUNTED SEASONS | I3: EXCLUDED PARTIALS
A4: =COUNTA('Research Tracker'!A11:A57) -> 47 | C4: =COUNTA(A8:A136) -> 129 | E4: =COUNT(G8:G136) -> 103 | G4: =COUNTIFS(H8:H136,"Yes",F8:F136,">0") -> 114 | I4: =COUNTIF(H8:H136,"No") -> 2
A6: Method: Premier League only. Outfield usage is minutes; goalkeeper usage is matches. A season counts only when usage is above zero and Include in Metrics = Yes. The average rating is an unweighted mean of the available FotMob season averages. Zero-minute seasons and ratings not published by FotMob remain blank. Tiny partial departure seasons are excluded where agreed.
A7: Player | B7: Pos | C7: Permanent Transfer Season | D7: Palace Season | E7: Usage Unit | F7: Usage | G7: FotMob Rating | H7: Include in Metrics | I7: Counts as Season | J7: Data Origin | K7: Source URL | L7: Notes
A8: Mamadou Sakho | B8: DF | C8: 2017/18 | D8: 2017/18 | E8: Minutes | F8: 1600 | G8: 6.74 | H8: Yes | I8: =IF(AND(H8="Yes",F8>0),"Yes","No") -> Yes | J8: User-provided FotMob | K8: https://www.fotmob.com/teams/9826/overview/crystal-palace
A9: Mamadou Sakho | B9: DF | C9: 2017/18 | D9: 2018/19 | E9: Minutes | F9: 2417 | G9: 6.68 | H9: Yes | I9: =IF(AND(H9="Yes",F9>0),"Yes","No") -> Yes | J9: User-provided FotMob | K9: https://www.fotmob.com/teams/9826/overview/crystal-palace
A10: Mamadou Sakho | B10: DF | C10: 2017/18 | D10: 2019/20 | E10: Minutes | F10: 931 | G10: 6.16 | H10: Yes | I10: =IF(AND(H10="Yes",F10>0),"Yes","No") -> Yes | J10: User-provided FotMob | K10: https://www.fotmob.com/teams/9826/overview/crystal-palace
A11: Mamadou Sakho | B11: DF | C11: 2017/18 | D11: 2020/21 | E11: Minutes | F11: 275 | G11: 6.28 | H11: Yes | I11: =IF(AND(H11="Yes",F11>0),"Yes","No") -> Yes | J11: User-provided FotMob | K11: https://www.fotmob.com/teams/9826/overview/crystal-palace
A12: Alexander Sørloth | B12: FW | C12: 2017/18 | D12: 2017/18 | E12: Minutes | F12: 360 | G12: 6.69 | H12: Yes | I12: =IF(AND(H12="Yes",F12>0),"Yes","No") -> Yes | J12: User-provided FotMob | K12: https://www.fotmob.com/teams/9826/overview/crystal-palace
A13: Alexander Sørloth | B13: FW | C13: 2017/18 | D13: 2018/19 | E13: Minutes | F13: 173 | G13: 6.08 | H13: Yes | I13: =IF(AND(H13="Yes",F13>0),"Yes","No") -> Yes | J13: User-provided FotMob | K13: https://www.fotmob.com/teams/9826/overview/crystal-palace
A14: Jaïro Riedewald | B14: MD | C14: 2017/18 | D14: 2017/18 | E14: Minutes | F14: 435 | G14: 6.31 | H14: Yes | I14: =IF(AND(H14="Yes",F14>0),"Yes","No") -> Yes | J14: User-provided FotMob | K14: https://www.fotmob.com/teams/9826/overview/crystal-palace
A15: Jaïro Riedewald | B15: MD | C15: 2017/18 | D15: 2018/19 | E15: Minutes | F15: 0 | H15: Yes | I15: =IF(AND(H15="Yes",F15>0),"Yes","No") -> No | J15: User-provided FotMob | K15: https://www.fotmob.com/teams/9826/overview/crystal-palace | L15: 0-minute seasons do not count as seasons played.
A16: Jaïro Riedewald | B16: MD | C16: 2017/18 | D16: 2019/20 | E16: Minutes | F16: 764 | G16: 6.33 | H16: Yes | I16: =IF(AND(H16="Yes",F16>0),"Yes","No") -> Yes | J16: User-provided FotMob | K16: https://www.fotmob.com/teams/9826/overview/crystal-palace
A17: Jaïro Riedewald | B17: MD | C17: 2017/18 | D17: 2020/21 | E17: Minutes | F17: 1817 | G17: 6.52 | H17: Yes | I17: =IF(AND(H17="Yes",F17>0),"Yes","No") -> Yes | J17: User-provided FotMob | K17: https://www.fotmob.com/teams/9826/overview/crystal-palace
A18: Jaïro Riedewald | B18: MD | C18: 2017/18 | D18: 2021/22 | E18: Minutes | F18: 116 | G18: 6.27 | H18: Yes | I18: =IF(AND(H18="Yes",F18>0),"Yes","No") -> Yes | J18: User-provided FotMob | K18: https://www.fotmob.com/teams/9826/overview/crystal-palace
A19: Jaïro Riedewald | B19: MD | C19: 2017/18 | D19: 2022/23 | E19: Minutes | F19: 60 | G19: 6.6 | H19: Yes | I19: =IF(AND(H19="Yes",F19>0),"Yes","No") -> Yes | J19: User-provided FotMob | K19: https://www.fotmob.com/teams/9826/overview/crystal-palace
A20: Jaïro Riedewald | B20: MD | C20: 2017/18 | D20: 2023/24 | E20: Minutes | F20: 229 | G20: 6.41 | H20: Yes | I20: =IF(AND(H20="Yes",F20>0),"Yes","No") -> Yes | J20: User-provided FotMob | K20: https://www.fotmob.com/teams/9826/overview/crystal-palace
A21: Jarosław Jach | B21: DF | C21: 2017/18 | D21: 2017/18 | E21: Minutes | F21: 0 | H21: Yes | I21: =IF(AND(H21="Yes",F21>0),"Yes","No") -> No | J21: User-provided FotMob | K21: https://www.fotmob.com/teams/9826/overview/crystal-palace | L21: No Palace Premier League minutes.
A22: Diego Cavalieri | B22: GK | C22: 2017/18 | D22: 2017/18 | E22: Matches | F22: 0 | H22: Yes | I22: =IF(AND(H22="Yes",F22>0),"Yes","No") -> No | J22: User-provided FotMob | K22: https://www.fotmob.com/teams/9826/overview/crystal-palace | L22: No Palace Premier League appearances.
A23: Cheikhou Kouyaté | B23: MD | C23: 2018/19 | D23: 2018/19 | E23: Minutes | F23: 1897 | G23: 6.46 | H23: Yes | I23: =IF(AND(H23="Yes",F23>0),"Yes","No") -> Yes | J23: User-provided FotMob | K23: https://www.fotmob.com/teams/9826/overview/crystal-palace
A24: Cheikhou Kouyaté | B24: MD | C24: 2018/19 | D24: 2019/20 | E24: Minutes | F24: 2535 | G24: 6.58 | H24: Yes | I24: =IF(AND(H24="Yes",F24>0),"Yes","No") -> Yes | J24: User-provided FotMob | K24: https://www.fotmob.com/teams/9826/overview/crystal-palace
A25: Cheikhou Kouyaté | B25: MD | C25: 2018/19 | D25: 2020/21 | E25: Minutes | F25: 3123 | G25: 6.52 | H25: Yes | I25: =IF(AND(H25="Yes",F25>0),"Yes","No") -> Yes | J25: User-provided FotMob | K25: https://www.fotmob.com/teams/9826/overview/crystal-palace
A26: Cheikhou Kouyaté | B26: MD | C26: 2018/19 | D26: 2021/22 | E26: Minutes | F26: 1978 | G26: 6.99 | H26: Yes | I26: =IF(AND(H26="Yes",F26>0),"Yes","No") -> Yes | J26: User-provided FotMob | K26: https://www.fotmob.com/teams/9826/overview/crystal-palace
A27: Max Meyer | B27: MD | C27: 2018/19 | D27: 2018/19 | E27: Minutes | F27: 1410 | G27: 6.47 | H27: Yes | I27: =IF(AND(H27="Yes",F27>0),"Yes","No") -> Yes | J27: User-provided FotMob | K27: https://www.fotmob.com/teams/9826/overview/crystal-palace
A28: Max Meyer | B28: MD | C28: 2018/19 | D28: 2019/20 | E28: Minutes | F28: 650 | G28: 6.02 | H28: Yes | I28: =IF(AND(H28="Yes",F28>0),"Yes","No") -> Yes | J28: User-provided FotMob | K28: https://www.fotmob.com/teams/9826/overview/crystal-palace
A29: Max Meyer | B29: MD | C29: 2018/19 | D29: 2020/21 | E29: Minutes | F29: 0 | H29: Yes | I29: =IF(AND(H29="Yes",F29>0),"Yes","No") -> No | J29: User-provided FotMob | K29: https://www.fotmob.com/teams/9826/overview/crystal-palace | L29: 0-minute season does not count.
A30: Bakary Sako | B30: FW | C30: 2018/19 | D30: 2018/19 | E30: Minutes | F30: 26 | G30: 5.87 | H30: Yes | I30: =IF(AND(H30="Yes",F30>0),"Yes","No") -> Yes | J30: User-provided FotMob | K30: https://www.fotmob.com/teams/9826/overview/crystal-palace
A31: Vicente Guaita | B31: GK | C31: 2018/19 | D31: 2018/19 | E31: Matches | F31: 20 | G31: 6.44 | H31: Yes | I31: =IF(AND(H31="Yes",F31>0),"Yes","No") -> Yes | J31: User-provided FotMob | K31: https://www.fotmob.com/teams/9826/overview/crystal-palace
A32: Vicente Guaita | B32: GK | C32: 2018/19 | D32: 2019/20 | E32: Matches | F32: 35 | G32: 6.46 | H32: Yes | I32: =IF(AND(H32="Yes",F32>0),"Yes","No") -> Yes | J32: User-provided FotMob | K32: https://www.fotmob.com/teams/9826/overview/crystal-palace
A33: Vicente Guaita | B33: GK | C33: 2018/19 | D33: 2020/21 | E33: Matches | F33: 37 | G33: 6.13 | H33: Yes | I33: =IF(AND(H33="Yes",F33>0),"Yes","No") -> Yes | J33: User-provided FotMob | K33: https://www.fotmob.com/teams/9826/overview/crystal-palace
A34: Vicente Guaita | B34: GK | C34: 2018/19 | D34: 2021/22 | E34: Matches | F34: 30 | G34: 6.65 | H34: Yes | I34: =IF(AND(H34="Yes",F34>0),"Yes","No") -> Yes | J34: User-provided FotMob | K34: https://www.fotmob.com/teams/9826/overview/crystal-palace
A35: Vicente Guaita | B35: GK | C35: 2018/19 | D35: 2022/23 | E35: Matches | F35: 27 | G35: 6.66 | H35: Yes | I35: =IF(AND(H35="Yes",F35>0),"Yes","No") -> Yes | J35: User-provided FotMob | K35: https://www.fotmob.com/teams/9826/overview/crystal-palace
A36: James McCarthy | B36: MD | C36: 2019/20 | D36: 2019/20 | E36: Minutes | F36: 1672 | G36: 6.42 | H36: Yes | I36: =IF(AND(H36="Yes",F36>0),"Yes","No") -> Yes | J36: User-provided FotMob | K36: https://www.fotmob.com/teams/9826/overview/crystal-palace
A37: James McCarthy | B37: MD | C37: 2019/20 | D37: 2020/21 | E37: Minutes | F37: 823 | G37: 6.48 | H37: Yes | I37: =IF(AND(H37="Yes",F37>0),"Yes","No") -> Yes | J37: User-provided FotMob | K37: https://www.fotmob.com/teams/9826/overview/crystal-palace
A38: Jordan Ayew | B38: FW | C38: 2019/20 | D38: 2019/20 | E38: Minutes | F38: 3160 | G38: 6.48 | H38: Yes | I38: =IF(AND(H38="Yes",F38>0),"Yes","No") -> Yes | J38: User-provided FotMob | K38: https://www.fotmob.com/teams/9826/overview/crystal-palace | L38: The isolated 2024/25 Palace cameo is excluded as agreed.
A39: Jordan Ayew | B39: FW | C39: 2019/20 | D39: 2020/21 | E39: Minutes | F39: 2097 | G39: 6.38 | H39: Yes | I39: =IF(AND(H39="Yes",F39>0),"Yes","No") -> Yes | J39: User-provided FotMob | K39: https://www.fotmob.com/teams/9826/overview/crystal-palace | L39: The isolated 2024/25 Palace cameo is excluded as agreed.
A40: Jordan Ayew | B40: FW | C40: 2019/20 | D40: 2021/22 | E40: Minutes | F40: 2023 | G40: 6.75 | H40: Yes | I40: =IF(AND(H40="Yes",F40>0),"Yes","No") -> Yes | J40: User-provided FotMob | K40: https://www.fotmob.com/teams/9826/overview/crystal-palace | L40: The isolated 2024/25 Palace cameo is excluded as agreed.
A41: Jordan Ayew | B41: FW | C41: 2019/20 | D41: 2022/23 | E41: Minutes | F41: 2720 | G41: 6.84 | H41: Yes | I41: =IF(AND(H41="Yes",F41>0),"Yes","No") -> Yes | J41: User-provided FotMob | K41: https://www.fotmob.com/teams/9826/overview/crystal-palace | L41: The isolated 2024/25 Palace cameo is excluded as agreed.
A42: Jordan Ayew | B42: FW | C42: 2019/20 | D42: 2023/24 | E42: Minutes | F42: 2594 | G42: 7 | H42: Yes | I42: =IF(AND(H42="Yes",F42>0),"Yes","No") -> Yes | J42: User-provided FotMob | K42: https://www.fotmob.com/teams/9826/overview/crystal-palace | L42: The isolated 2024/25 Palace cameo is excluded as agreed.
...
